<?xml version="1.0"?>
  <sdf version="1.4">

    <model name="myartbot">
    <static>true</static>                                       <!--CHASSIS LINK-->
      <link name="chassis">
        <pose>0 0 0.05 0 0 0</pose>

        <collision name="collision">
          <geometry>
            <box>
              <size>0.4 0.2 0.05</size>
            </box>
          </geometry>
        </collision>

        <visual name="visual">
          <geometry>
            <box>
              <size>0.4 0.2 0.05</size>
            </box>
          </geometry>
        </visual>
      </link>

      <link name="wheelfl">                                   <!--FRONT LEFT WHEEL LINK-->
        <pose>0.1 0.115 0.05 0 1.5707 1.5707</pose>

        <collision name="collision">
          <geometry>
            <cylinder>
              <radius>0.05</radius>
              <length>0.03</length>
            </cylinder>
          </geometry>
        </collision>

        <visual name="visual">
          <geometry>
            <cylinder>
              <radius>0.05</radius>
              <length>0.03</length>
            </cylinder>
          </geometry>
        </visual>
      </link>

      <joint name="wheelfl_to_chassis" type="universal">
        <pose>0 0 0 0 0 0</pose>
        <child>wheelfl</child>
        <parent>chassis</parent>
        <axis>
          <xyz>0 1 0</xyz>
          <limit>
            <lower>-3.141592</lower>
            <upper>3.141592</upper>
          </limit>
        </axis>
        <axis2>
          <xyz>0 0 1</xyz>
          <limit>
            <lower>-0.523598</lower>
            <upper>0.523598</upper>
          </limit>
        </axis2>
      </joint>

      <link name="wheelfr">                                 <!--FRONT RIGHT WHEEL LINK-->
        <pose>0.1 -0.115 0.05 0 1.5707 1.5707</pose>

        <collision name="collision">
          <geometry>
            <cylinder>
              <radius>0.05</radius>
              <length>0.03</length>
            </cylinder>
          </geometry>
        </collision>

        <visual name="visual">
          <geometry>
            <cylinder>
              <radius>0.05</radius>
              <length>0.03</length>
            </cylinder>
          </geometry>
        </visual>
      </link>

      <joint name="wheelfr_to_chassis" type="universal">
        <pose>0 0 0 0 0 0</pose>
        <child>wheelfr</child>
        <parent>chassis</parent>
        <axis>
          <xyz>0 1 0</xyz>
          <limit>
            <lower>-3.141592</lower>
            <upper>3.141592</upper>
          </limit>
        </axis>
        <axis2>
          <xyz>0 0 1</xyz>
          <limit>
            <lower>-0.523598</lower>
            <upper>0.523598</upper>
          </limit>
        </axis2>
      </joint>

      <link name="wheelbl">                                 <!--BACK LEFT WHEEL LINK-->
        <pose>-0.1 0.115 0.05 0 1.5707 1.5707</pose>

        <collision name="collision">
          <geometry>
            <cylinder>
              <radius>0.05</radius>
              <length>0.03</length>
            </cylinder>
          </geometry>
        </collision>

        <visual name="visual">
          <geometry>
            <cylinder>
              <radius>0.05</radius>
              <length>0.03</length>
            </cylinder>
          </geometry>
        </visual>
      </link>

      <joint name="wheelbl_to_chassis" type="revolute">
        <pose>0 0 0 0 0 0</pose>
        <child>wheelbl</child>
        <parent>chassis</parent>
        <axis>
          <xyz>0 1 0</xyz>
        </axis>
      </joint>

      <link name="wheelbr">                                  <!--BACK RIGHT WHEEL LINK-->
        <pose>-0.1 -0.115 0.05 0 1.5707 1.5707</pose>

        <collision name="collision">
          <geometry>
            <cylinder>
              <radius>0.05</radius>
              <length>0.03</length>
            </cylinder>
          </geometry>
        </collision>

        <visual name="visual">
          <geometry>
            <cylinder>
              <radius>0.05</radius>
              <length>0.03</length>
            </cylinder>
          </geometry>
        </visual>
      </link>

      <joint name="wheelbr_to_chassis" type="revolute">
        <pose>0 0 0 0 0 0</pose>
        <child>wheelbr</child>
        <parent>chassis</parent>
        <axis>
          <xyz>0 1 0</xyz>
        </axis>
      </joint>

      <link name="link">

      <sensor type="camera" name="my_sensor">
        <camera>
          <horizontal_fov>2.1679</horizontal_fov>
          <image>
            <width>320</width>
            <height>240</height>
          </image>
          <clip>
            <near>0.1</near>
            <far>100</far>
          </clip>
        </camera>
        <always_on>1</always_on>
        <update_rate>30</update_rate>
        <visualize>true</visualize>
        <plugin name="CameraPublisher" filename="libgazebo_ros_camera.so"/>
        </plugin>
      </sensor>

      </link>

      <joint name="camera_to_chassis" type="revolute">
        <parent>chassis</parent>
        <child>link</child>
        <pose>0 0 0 0 0 0</pose>
        <axis>
          <xyz>0 0 1</xyz>
          <limit>
            <upper>0</upper>
            <lower>0</lower>
          </limit>
        </axis>
      </joint>

    </model>
  </sdf>
